2022-01-05 16:56:28 WARNING (SyncWorker_2) [homeassistant.loader] We found a custom integration hacs which has not been tested by Home Assistant. This component might cause stability problems, be sure to disable it if you experience issues with Home Assistant
2022-01-05 16:56:28 WARNING (SyncWorker_0) [homeassistant.loader] We found a custom integration afvalwijzer which has not been tested by Home Assistant. This component might cause stability problems, be sure to disable it if you experience issues with Home Assistant
2022-01-05 16:56:28 WARNING (SyncWorker_1) [homeassistant.loader] We found a custom integration unifiprotect which has not been tested by Home Assistant. This component might cause stability problems, be sure to disable it if you experience issues with Home Assistant
2022-01-05 16:56:29 WARNING (MainThread) [homeassistant.components.lovelace] Cannot register panel at lovelace-mobile, it is already defined in <homeassistant.components.lovelace.dashboard.LovelaceYAML object at 0x7f56ee60b250>
2022-01-05 16:56:32 ERROR (MainThread) [homeassistant.components.weather] The buienradar platform for the weather integration does not support platform setup. Please remove it from your config.
2022-01-05 16:56:35 ERROR (MainThread) [homeassistant.components.mqtt] Failed to connect to MQTT server due to exception: [Errno 113] Host is unreachable
2022-01-05 16:56:48 WARNING (MainThread) [homeassistant.config_entries] Config entry 'UniFi Controller' for unifiprotect integration not ready yet: Error requesting data from unifi.home.cetana.net: Cannot connect to host unifi.home.cetana.net:443 ssl:False [Name does not resolve]; Retrying in background
2022-01-05 16:56:48 ERROR (MainThread) [homeassistant.components.unifi] Error connecting to the UniFi Network at unifi.home.cetana.net: Error requesting data from unifi.home.cetana.net: Cannot connect to host unifi.home.cetana.net:443 ssl:default [Name does not resolve]
2022-01-05 16:56:48 WARNING (MainThread) [homeassistant.config_entries] Config entry 'Cetana' for unifi integration not ready yet; Retrying in background
2022-01-05 16:56:49 WARNING (MainThread) [homeassistant.components.light] Platform netatmo not ready yet: None; Retrying in background in 30 seconds
2022-01-05 16:56:49 WARNING (MainThread) [homeassistant.components.select] Platform netatmo not ready yet: None; Retrying in background in 30 seconds
2022-01-05 16:56:49 ERROR (MainThread) [homeassistant.components.zwave_js] Discovery for value Value(value_id='19-50-0-value-1025') on device 'Wasmachine' (Node(node_id=19)) will be skipped: Value Value(value_id='19-50-0-value-1025') has unknown data in the following location: metadata.cc_specific.meterType. A reinterview of node Node(node_id=19) may correct this issue, but if it doesn't, please report this issue as it may be caused by either an upstream issue with the driver or missing support for this data in the library
2022-01-05 16:56:49 ERROR (MainThread) [homeassistant.components.zwave_js] Discovery for value Value(value_id='19-50-0-value-1') on device 'Wasmachine' (Node(node_id=19)) will be skipped: Value Value(value_id='19-50-0-value-1') has unknown data in the following location: metadata.cc_specific.meterType. A reinterview of node Node(node_id=19) may correct this issue, but if it doesn't, please report this issue as it may be caused by either an upstream issue with the driver or missing support for this data in the library
2022-01-05 16:56:49 ERROR (MainThread) [homeassistant.components.zwave_js] Discovery for value Value(value_id='19-50-0-value-328961') on device 'Wasmachine' (Node(node_id=19)) will be skipped: Value Value(value_id='19-50-0-value-328961') has unknown data in the following location: metadata.cc_specific.scale. A reinterview of node Node(node_id=19) may correct this issue, but if it doesn't, please report this issue as it may be caused by either an upstream issue with the driver or missing support for this data in the library
2022-01-05 16:56:49 ERROR (MainThread) [homeassistant.components.zwave_js] Discovery for value Value(value_id='20-50-0-value-591107') on device 'Droger' (Node(node_id=20)) will be skipped: Value Value(value_id='20-50-0-value-591107') has unknown data in the following location: metadata.cc_specific.meterType. A reinterview of node Node(node_id=20) may correct this issue, but if it doesn't, please report this issue as it may be caused by either an upstream issue with the driver or missing support for this data in the library
2022-01-05 16:56:49 ERROR (MainThread) [homeassistant.components.zwave_js] Discovery for value Value(value_id='22-50-0-value-197633') on device 'Bureau' (Node(node_id=22)) will be skipped: Value Value(value_id='22-50-0-value-197633') has unknown data in the following location: metadata.cc_specific.scale. A reinterview of node Node(node_id=22) may correct this issue, but if it doesn't, please report this issue as it may be caused by either an upstream issue with the driver or missing support for this data in the library
2022-01-05 16:56:49 ERROR (MainThread) [homeassistant.components.zwave_js] Discovery for value Value(value_id='22-50-0-value-590849') on device 'Bureau' (Node(node_id=22)) will be skipped: Value Value(value_id='22-50-0-value-590849') has unknown data in the following location: metadata.cc_specific.meterType. A reinterview of node Node(node_id=22) may correct this issue, but if it doesn't, please report this issue as it may be caused by either an upstream issue with the driver or missing support for this data in the library
2022-01-05 16:56:49 ERROR (MainThread) [homeassistant.components.zwave_js] Discovery for value Value(value_id='22-50-0-value-1114625') on device 'Bureau' (Node(node_id=22)) will be skipped: Value Value(value_id='22-50-0-value-1114625') has unknown data in the following location: metadata.cc_specific.meterType. A reinterview of node Node(node_id=22) may correct this issue, but if it doesn't, please report this issue as it may be caused by either an upstream issue with the driver or missing support for this data in the library
2022-01-05 16:56:49 ERROR (MainThread) [homeassistant.components.zwave_js] Discovery for value Value(value_id='22-50-0-value-1115393') on device 'Bureau' (Node(node_id=22)) will be skipped: Value Value(value_id='22-50-0-value-1115393') has unknown data in the following location: metadata.cc_specific.meterType. A reinterview of node Node(node_id=22) may correct this issue, but if it doesn't, please report this issue as it may be caused by either an upstream issue with the driver or missing support for this data in the library
2022-01-05 16:56:49 ERROR (MainThread) [homeassistant.components.zwave_js] Discovery for value Value(value_id='22-50-0-value-1') on device 'Bureau' (Node(node_id=22)) will be skipped: Value Value(value_id='22-50-0-value-1') has unknown data in the following location: metadata.cc_specific.meterType. A reinterview of node Node(node_id=22) may correct this issue, but if it doesn't, please report this issue as it may be caused by either an upstream issue with the driver or missing support for this data in the library
2022-01-05 16:56:49 ERROR (MainThread) [homeassistant.components.zwave_js] Discovery for value Value(value_id='22-50-0-value-589825') on device 'Bureau' (Node(node_id=22)) will be skipped: Value Value(value_id='22-50-0-value-589825') has unknown data in the following location: metadata.cc_specific.meterType. A reinterview of node Node(node_id=22) may correct this issue, but if it doesn't, please report this issue as it may be caused by either an upstream issue with the driver or missing support for this data in the library
2022-01-05 16:56:49 ERROR (MainThread) [homeassistant.components.zwave_js] Discovery for value Value(value_id='28-50-0-value-656385') on device 'CV installatie' (Node(node_id=28)) will be skipped: Value Value(value_id='28-50-0-value-656385') has unknown data in the following location: metadata.cc_specific.meterType. A reinterview of node Node(node_id=28) may correct this issue, but if it doesn't, please report this issue as it may be caused by either an upstream issue with the driver or missing support for this data in the library
2022-01-05 16:56:53 ERROR (MainThread) [homeassistant.components.unifi] Error connecting to the UniFi Network at unifi.home.cetana.net: Error requesting data from unifi.home.cetana.net: Cannot connect to host unifi.home.cetana.net:443 ssl:default [Name does not resolve]
2022-01-05 16:56:53 WARNING (MainThread) [homeassistant.components.homekit] The bridge Home Assistant Bridge has entity media_player.sf_office_cast_tv. For best performance, and to prevent unexpected unavailability, create and pair a separate HomeKit instance in accessory mode for this entity
2022-01-05 16:57:03 ERROR (MainThread) [homeassistant.components.unifi] Error connecting to the UniFi Network at unifi.home.cetana.net: Error requesting data from unifi.home.cetana.net: Cannot connect to host unifi.home.cetana.net:443 ssl:default [Name does not resolve]
2022-01-05 16:57:23 ERROR (MainThread) [homeassistant.components.unifi] Error connecting to the UniFi Network at unifi.home.cetana.net: Error requesting data from unifi.home.cetana.net: Cannot connect to host unifi.home.cetana.net:443 ssl:default [Name does not resolve]
2022-01-05 16:58:03 ERROR (MainThread) [homeassistant.components.unifi] Error connecting to the UniFi Network at unifi.home.cetana.net: Error requesting data from unifi.home.cetana.net: Cannot connect to host unifi.home.cetana.net:443 ssl:default [Name does not resolve]
2022-01-05 16:59:23 ERROR (MainThread) [homeassistant.components.unifi] Error connecting to the UniFi Network at unifi.home.cetana.net: Error requesting data from unifi.home.cetana.net: Cannot connect to host unifi.home.cetana.net:443 ssl:default [Name does not resolve]
2022-01-05 17:00:43 ERROR (MainThread) [homeassistant.components.unifi] Error connecting to the UniFi Network at unifi.home.cetana.net: Error requesting data from unifi.home.cetana.net: Cannot connect to host unifi.home.cetana.net:443 ssl:default [Name does not resolve]
2022-01-05 17:02:03 ERROR (MainThread) [homeassistant.components.unifi] Error connecting to the UniFi Network at unifi.home.cetana.net: Error requesting data from unifi.home.cetana.net: Cannot connect to host unifi.home.cetana.net:443 ssl:default [Name does not resolve]
2022-01-05 17:03:23 ERROR (MainThread) [homeassistant.components.unifi] Error connecting to the UniFi Network at unifi.home.cetana.net: Error requesting data from unifi.home.cetana.net: Cannot connect to host unifi.home.cetana.net:443 ssl:default [Name does not resolve]
2022-01-05 17:03:24 ERROR (MainThread) [homeassistant.components.http.forwarded] A request from a reverse proxy was received from 172.30.33.4, but your HTTP integration is not set-up for reverse proxies
2022-01-05 17:03:24 ERROR (MainThread) [homeassistant.components.http.forwarded] A request from a reverse proxy was received from 172.30.33.4, but your HTTP integration is not set-up for reverse proxies
2022-01-05 17:03:39 ERROR (MainThread) [homeassistant.components.http.forwarded] A request from a reverse proxy was received from 172.30.33.4, but your HTTP integration is not set-up for reverse proxies
2022-01-05 17:03:39 ERROR (MainThread) [homeassistant.components.http.forwarded] A request from a reverse proxy was received from 172.30.33.4, but your HTTP integration is not set-up for reverse proxies
2022-01-05 17:03:40 ERROR (MainThread) [homeassistant.components.http.forwarded] A request from a reverse proxy was received from 172.30.33.4, but your HTTP integration is not set-up for reverse proxies
2022-01-05 17:03:40 ERROR (MainThread) [homeassistant.components.http.forwarded] A request from a reverse proxy was received from 172.30.33.4, but your HTTP integration is not set-up for reverse proxies
2022-01-05 17:04:43 ERROR (MainThread) [homeassistant.components.unifi] Error connecting to the UniFi Network at unifi.home.cetana.net: Error requesting data from unifi.home.cetana.net: Cannot connect to host unifi.home.cetana.net:443 ssl:default [Name does not resolve]
2022-01-05 17:06:03 ERROR (MainThread) [homeassistant.components.unifi] Error connecting to the UniFi Network at unifi.home.cetana.net: Error requesting data from unifi.home.cetana.net: Cannot connect to host unifi.home.cetana.net:443 ssl:default [Name does not resolve]
2022-01-05 17:06:55 ERROR (MainThread) [aiohttp.server] Error handling request
Traceback (most recent call last):
  File "/usr/local/lib/python3.9/site-packages/aiohttp/web_protocol.py", line 334, in data_received
    messages, upgraded, tail = self._request_parser.feed_data(data)
  File "aiohttp/_http_parser.pyx", line 551, in aiohttp._http_parser.HttpParser.feed_data
aiohttp.http_exceptions.BadStatusLine: 400, message="Bad status line 'Invalid method encountered'"
2022-01-05 17:06:55 ERROR (MainThread) [aiohttp.server] Error handling request
Traceback (most recent call last):
  File "/usr/local/lib/python3.9/site-packages/aiohttp/web_protocol.py", line 334, in data_received
    messages, upgraded, tail = self._request_parser.feed_data(data)
  File "aiohttp/_http_parser.pyx", line 551, in aiohttp._http_parser.HttpParser.feed_data
aiohttp.http_exceptions.BadStatusLine: 400, message="Bad status line 'Invalid method encountered'"
2022-01-05 17:06:58 ERROR (MainThread) [aiohttp.server] Error handling request
Traceback (most recent call last):
  File "/usr/local/lib/python3.9/site-packages/aiohttp/web_protocol.py", line 334, in data_received
    messages, upgraded, tail = self._request_parser.feed_data(data)
  File "aiohttp/_http_parser.pyx", line 551, in aiohttp._http_parser.HttpParser.feed_data
aiohttp.http_exceptions.BadStatusLine: 400, message="Bad status line 'Invalid method encountered'"
2022-01-05 17:06:58 ERROR (MainThread) [aiohttp.server] Error handling request
Traceback (most recent call last):
  File "/usr/local/lib/python3.9/site-packages/aiohttp/web_protocol.py", line 334, in data_received
    messages, upgraded, tail = self._request_parser.feed_data(data)
  File "aiohttp/_http_parser.pyx", line 551, in aiohttp._http_parser.HttpParser.feed_data
aiohttp.http_exceptions.BadStatusLine: 400, message="Bad status line 'Invalid method encountered'"
2022-01-05 17:07:06 ERROR (MainThread) [aiohttp.server] Error handling request
Traceback (most recent call last):
  File "/usr/local/lib/python3.9/site-packages/aiohttp/web_protocol.py", line 334, in data_received
    messages, upgraded, tail = self._request_parser.feed_data(data)
  File "aiohttp/_http_parser.pyx", line 551, in aiohttp._http_parser.HttpParser.feed_data
aiohttp.http_exceptions.BadStatusLine: 400, message="Bad status line 'Invalid method encountered'"
2022-01-05 17:07:06 ERROR (MainThread) [aiohttp.server] Error handling request
Traceback (most recent call last):
  File "/usr/local/lib/python3.9/site-packages/aiohttp/web_protocol.py", line 334, in data_received
    messages, upgraded, tail = self._request_parser.feed_data(data)
  File "aiohttp/_http_parser.pyx", line 551, in aiohttp._http_parser.HttpParser.feed_data
aiohttp.http_exceptions.BadStatusLine: 400, message="Bad status line 'Invalid method encountered'"
2022-01-05 17:07:11 ERROR (MainThread) [aiohttp.server] Error handling request
Traceback (most recent call last):
  File "/usr/local/lib/python3.9/site-packages/aiohttp/web_protocol.py", line 334, in data_received
    messages, upgraded, tail = self._request_parser.feed_data(data)
  File "aiohttp/_http_parser.pyx", line 551, in aiohttp._http_parser.HttpParser.feed_data
aiohttp.http_exceptions.BadStatusLine: 400, message="Bad status line 'Invalid method encountered'"
2022-01-05 17:07:11 ERROR (MainThread) [aiohttp.server] Error handling request
Traceback (most recent call last):
  File "/usr/local/lib/python3.9/site-packages/aiohttp/web_protocol.py", line 334, in data_received
    messages, upgraded, tail = self._request_parser.feed_data(data)
  File "aiohttp/_http_parser.pyx", line 551, in aiohttp._http_parser.HttpParser.feed_data
aiohttp.http_exceptions.BadStatusLine: 400, message="Bad status line 'Invalid method encountered'"
2022-01-05 17:07:23 ERROR (MainThread) [homeassistant.components.unifi] Error connecting to the UniFi Network at unifi.home.cetana.net: Error requesting data from unifi.home.cetana.net: Cannot connect to host unifi.home.cetana.net:443 ssl:default [Name does not resolve]
